Workbook

Sheet Storage 
A1: Emp. No. | B1: Employee Name | C1: OLD Whereabouts | D1: New whereabouts | E1: Old Equipment Trainings Required As per Facility | F1: New Equipment Trainings Required As per Facility | G1: SOP Trainings Required As per Facility | H1: Other Trainings Required | I1: Change status
A2: G0010 | B2: Norbert Mueller | C2: MM office | D2: =VLOOKUP('Storage '!A2,METADATA!A:G,7,FALSE) -> MM office | E2: 0 | F2: =VLOOKUP(D2,'Required trainings'!A:B,2,FALSE) -> 0 | G2: 1 | H2: 1 | I2: =IF(C2=D2,"no change","change") -> no change
A3: Q0011 | B3: Mohamed Farkan Mohamed Sareek | C3: Admin office | D3: =VLOOKUP('Storage '!A3,METADATA!A:G,7,FALSE) -> Admin office | E3: 0 | F3: =VLOOKUP(D3,'Required trainings'!A:B,2,FALSE) -> 0 | G3: 1 | H3: 1 | I3: =IF(C3=D3,"no change","yes") -> no change
A4: Q0041 | B4: Destiny Emmanuel | C4: AMH | D4: =VLOOKUP('Storage '!A4,METADATA!A:G,7,FALSE) -> AMH | E4: 8 | F4: =VLOOKUP(D4,'Required trainings'!A:B,2,FALSE) -> 8 | G4: 3 | H4: 1 | I4: =IF(C4=D4,"no change","yes") -> no change
A5: Q0042 | B5: Abdunaser Ahmed Aragaw | C5: CM2 | D5: =VLOOKUP('Storage '!A5,METADATA!A:G,7,FALSE) -> CM2 | E5: 18 | F5: =VLOOKUP(D5,'Required trainings'!A:B,2,FALSE) -> 18 | G5: 4 | H5: 3 | I5: =IF(C5=D5,"no change","yes") -> no change
A6: Q0048 | B6: Rizardo Villalobos | C6: CM4 | D6: =VLOOKUP('Storage '!A6,METADATA!A:G,7,FALSE) -> CM4 | E6: 18 | F6: =VLOOKUP(D6,'Required trainings'!A:B,2,FALSE) -> 18 | G6: 4 | H6: 3 | I6: =IF(C6=D6,"no change","yes") -> no change
A7: Q0055 | B7: Chidanand Bhaskara Chaithanya | C7: QDF office | D7: =VLOOKUP('Storage '!A7,METADATA!A:G,7,FALSE) -> QDF office | E7: 0 | F7: =VLOOKUP(D7,'Required trainings'!A:B,2,FALSE) -> 0 | G7: 3 | H7: 1 | I7: =IF(C7=D7,"no change","yes") -> no change
A8: Q0058 | B8: Mahesh Ramachandra | C8: Technical support office | D8: =VLOOKUP('Storage '!A8,METADATA!A:G,7,FALSE) -> Technical support office | E8: 0 | F8: =VLOOKUP(D8,'Required trainings'!A:B,2,FALSE) -> 0 | G8: 3 | H8: 1 | I8: =IF(C8=D8,"no change","yes") -> no change
A9: Q0065 | B9: Joel Cabrillos Misa | C9: CM3 | D9: =VLOOKUP('Storage '!A9,METADATA!A:G,7,FALSE) -> CM3 | E9: 18 | F9: =VLOOKUP(D9,'Required trainings'!A:B,2,FALSE) -> 18 | G9: 4 | H9: 3 | I9: =IF(C9=D9,"no change","yes") -> no change
A10: Q0068 | B10: Ericson Murcillos Victorino | C10: CM1 | D10: =VLOOKUP('Storage '!A10,METADATA!A:G,7,FALSE) -> AMH | E10: 18 | F10: =VLOOKUP(D10,'Required trainings'!A:B,2,FALSE) -> 8 | G10: 4 | H10: 3 | I10: =IF(C10=D10,"no change","yes") -> yes
A11: Q0070 | B11: Fernan Dela Cruz | C11: Technical support office | D11: =VLOOKUP('Storage '!A11,METADATA!A:G,7,FALSE) -> Technical support office | E11: 0 | F11: =VLOOKUP(D11,'Required trainings'!A:B,2,FALSE) -> 0 | G11: 3 | H11: 1 | I11: =IF(C11=D11,"no change","yes") -> no change
A12: Q0077 | B12: Bindu Pillai | C12: Technical support office | D12: =VLOOKUP('Storage '!A12,METADATA!A:G,7,FALSE) -> Technical support office | E12: 0 | F12: =VLOOKUP(D12,'Required trainings'!A:B,2,FALSE) -> 0 | G12: 1 | H12: 1 | I12: =IF(C12=D12,"no change","yes") -> no change
A13: Q0082 | B13: Philippe Musangilay Kubula | C13: Admin office | D13: =VLOOKUP('Storage '!A13,METADATA!A:G,7,FALSE) -> Admin office | E13: 0 | F13: =VLOOKUP(D13,'Required trainings'!A:B,2,FALSE) -> 0 | G13: 1 | H13: 1 | I13: =IF(C13=D13,"no change","yes") -> no change
A14: Q0090 | B14: Sandy De Vera Apigo | C14: CM1 | D14: =VLOOKUP('Storage '!A14,METADATA!A:G,7,FALSE) -> CM1 | E14: 18 | F14: =VLOOKUP(D14,'Required trainings'!A:B,2,FALSE) -> 18 | G14: 4 | H14: 3 | I14: =IF(C14=D14,"no change","yes") -> no change
... A22: Q0138 | B22: Joevergil Cajocson Dormitorio | C22: CM2 | D22: =VLOOKUP('Storage '!A22,METADATA!A:G,7,FALSE) -> CM2 | E22: 18 | F22: =VLOOKUP(D22,'Required trainings'!A:B,2,FALSE) -> 18 | G22: 4 | H22: 3 | I22: =IF(C22=D22,"no change","yes") -> no change
A23: Q0139 | B23: Ricky Catibog Katigbak | C23: QNL | D23: =VLOOKUP('Storage '!A23,METADATA!A:G,7,FALSE) -> QNL | E23: 0 | F23: =VLOOKUP(D23,'Required trainings'!A:B,2,FALSE) -> 0 | I23: =IF(C23=D23,"no change","yes") -> no change
A24: Q0149 | B24: Venice Mendova Jadloc | C24: DFWH | D24: =VLOOKUP('Storage '!A24,METADATA!A:G,7,FALSE) -> Resigned | E24: 16 | F24: =VLOOKUP(D24,'Required trainings'!A:B,2,FALSE) -> 0 | G24: 2 | H24: 1 | I24: =IF(C24=D24,"no change","yes") -> yes
A25: Q0150 | B25: Lemuel Celeste Anacleto | C25: CM3 | D25: =VLOOKUP('Storage '!A25,METADATA!A:G,7,FALSE) -> CM3 | E25: 18 | F25: =VLOOKUP(D25,'Required trainings'!A:B,2,FALSE) -> 18 | G25: 4 | H25: 3 | I25: =IF(C25=D25,"no change","yes") -> no change
A26: Q0158 | B26: Arnel Butiu Guevarra | C26: CM4 | D26: =VLOOKUP('Storage '!A26,METADATA!A:G,7,FALSE) -> CM4 | E26: 18 | F26: =VLOOKUP(D26,'Required trainings'!A:B,2,FALSE) -> 18 | G26: 4 | H26: 3 | I26: =IF(C26=D26,"no change","yes") -> no change
A27: Q0159 | B27: Jessie Jr. Alcuizar Hellera | C27: Admin office | D27: =VLOOKUP('Storage '!A27,METADATA!A:G,7,FALSE) -> Admin office | E27: 0 | F27: =VLOOKUP(D27,'Required trainings'!A:B,2,FALSE) -> 0 | G27: 1 | H27: 1 | I27: =IF(C27=D27,"no change","yes") -> no change
A28: Q0165 | B28: Noel Jarabe Riego | C28: AMH | D28: =VLOOKUP('Storage '!A28,METADATA!A:G,7,FALSE) -> Resigned | E28: 8 | F28: =VLOOKUP(D28,'Required trainings'!A:B,2,FALSE) -> 0 | I28: =IF(C28=D28,"no change","yes") -> yes
A29: Q0170 | B29: Edilberto Angsioco | C29: CM2 | D29: =VLOOKUP('Storage '!A29,METADATA!A:G,7,FALSE) -> CM2 | E29: 18 | F29: =VLOOKUP(D29,'Required trainings'!A:B,2,FALSE) -> 18 | G29: 4 | H29: 3 | I29: =IF(C29=D29,"no change","yes") -> no change
A30: Q0185 | B30: Jose Dino Constantino | C30: Admin office | D30: =VLOOKUP('Storage '!A30,METADATA!A:G,7,FALSE) -> Admin office | E30: 0 | F30: =VLOOKUP(D30,'Required trainings'!A:B,2,FALSE) -> 0 | G30: 1 | H30: 1 | I30: =IF(C30=D30,"no change","yes") -> no change
A31: Q0187 | B31: Regin Alis | C31: CM4 | D31: =VLOOKUP('Storage '!A31,METADATA!A:G,7,FALSE) -> CM4 | E31: 18 | F31: =VLOOKUP(D31,'Required trainings'!A:B,2,FALSE) -> 18 | G31: 4 | H31: 3 | I31: =IF(C31=D31,"no change","yes") -> no change
A32: Q0188 | B32: Restito Fabic | C32: Admin office | D32: =VLOOKUP('Storage '!A32,METADATA!A:G,7,FALSE) -> Admin office | E32: 0 | F32: =VLOOKUP(D32,'Required trainings'!A:B,2,FALSE) -> 0 | G32: 3 | H32: 1 | I32: =IF(C32=D32,"no change","yes") -> no change
A33: Q0194 | B33: Kamalanathan Poopalapillai | C33: Pantry | D33: =VLOOKUP('Storage '!A33,METADATA!A:G,7,FALSE) -> Pantry | E33: 0 | F33: =VLOOKUP(D33,'Required trainings'!A:B,2,FALSE) -> 0 | G33: 1 | H33: 1 | I33: =IF(C33=D33,"no change","yes") -> no change
A34: Q0206 | B34: Anil Kumara | C34: Pantry | D34: =VLOOKUP('Storage '!A34,METADATA!A:G,7,FALSE) -> Pantry | E34: 0 | F34: =VLOOKUP(D34,'Required trainings'!A:B,2,FALSE) -> 0 | G34: 1 | H34: 1 | I34: =IF(C34=D34,"no change","yes") -> no change
A35: Q0207 | B35: Lani Fernando Kachchakaduge | C35: PM2 | D35: =VLOOKUP('Storage '!A35,METADATA!A:G,7,FALSE) -> PM2 | E35: 15 | F35: =VLOOKUP(D35,'Required trainings'!A:B,2,FALSE) -> 15 | G35: 4 | H35: 3 | I35: =IF(C35=D35,"no change","yes") -> no change
A36: Q0208 | B36: Sampath Chamin | C36: PM3 | D36: =VLOOKUP('Storage '!A36,METADATA!A:G,7,FALSE) -> PM3 | E36: 15 | F36: =VLOOKUP(D36,'Required trainings'!A:B,2,FALSE) -> 15 | G36: 4 | H36: 3 | I36: =IF(C36=D36,"no change","yes") -> no change
A37: Q0216 | B37: Raymond Ian Montero | C37: Store room | D37: =VLOOKUP('Storage '!A37,METADATA!A:G,7,FALSE) -> Store room | E37: 0 | F37: =VLOOKUP(D37,'Required trainings'!A:B,2,FALSE) -> 0 | G37: 1 | H37: 1 | I37: =IF(C37=D37,"no change","yes") -> no change
A38: Q0219 | B38: James Magnaye Catapia | C38: CM2 | D38: =VLOOKUP('Storage '!A38,METADATA!A:G,7,FALSE) -> CM3 | E38: 18 | F38: =VLOOKUP(D38,'Required trainings'!A:B,2,FALSE) -> 18 | G38: 4 | H38: 3 | I38: =IF(C38=D38,"no change","yes") -> yes
A39: Q0229 | B39: Marty Tolosa Ambas | C39: PM4 | D39: =VLOOKUP('Storage '!A39,METADATA!A:G,7,FALSE) -> Resigned | E39: 15 | F39: =VLOOKUP(D39,'Required trainings'!A:B,2,FALSE) -> 0 | G39: 4 | H39: 3 | I39: =IF(C39=D39,"no change","yes") -> yes
A40: Q0234 | B40: Nove Manuel Menorisa Tagpuno | C40: CM1 | D40: =VLOOKUP('Storage '!A40,METADATA!A:G,7,FALSE) -> CM1 | E40: 18 | F40: =VLOOKUP(D40,'Required trainings'!A:B,2,FALSE) -> 18 | G40: 4 | H40: 3 | I40: =IF(C40=D40,"no change","yes") -> no change
... A69: Q0418 | B69: Nathaniel Laguidao Gamosa | C69: Projects | D69: =VLOOKUP('Storage '!A69,METADATA!A:G,7,FALSE) -> Projects | E69: 0 | F69: =VLOOKUP(D69,'Required trainings'!A:B,2,FALSE) -> 0 | G69: 3 | H69: 1 | I69: =IF(C69=D69,"no change","yes") -> no change
A70: Q0424 | B70: Ernesto JR Leona Campana | C70: Jordan | D70: =VLOOKUP('Storage '!A70,METADATA!A:G,7,FALSE) -> QNL | E70: 0 | F70: =VLOOKUP(D70,'Required trainings'!A:B,2,FALSE) -> 0 | I70: =IF(C70=D70,"no change","yes") -> yes
A71: Q0426 | B71: William Villanueva Gutierrez | C71: Projects | D71: =VLOOKUP('Storage '!A71,METADATA!A:G,7,FALSE) -> Projects | E71: 0 | F71: =VLOOKUP(D71,'Required trainings'!A:B,2,FALSE) -> 0 | G71: 1 | H71: 0 | I71: =IF(C71=D71,"no change","yes") -> no change
A72: Q0428 | B72: Conrado DE Guzman Vineza | C72: PM | D72: =VLOOKUP('Storage '!A72,METADATA!A:G,7,FALSE) -> PM3 | E72: 15 | F72: =VLOOKUP(D72,'Required trainings'!A:B,2,FALSE) -> 15 | G72: 4 | H72: 3 | I72: =IF(C72=D72,"no change","yes") -> yes
A73: Q0429 | B73: Elecer Hernandez Llamoso | C73: DFWH | D73: =VLOOKUP('Storage '!A73,METADATA!A:G,7,FALSE) -> DFWH | E73: 16 | F73: =VLOOKUP(D73,'Required trainings'!A:B,2,FALSE) -> 16 | G73: 3 | H73: 1 | I73: =IF(C73=D73,"no change","yes") -> no change
A74: Q0430 | B74: Elesor JR Cas Frondozo | C74: CBF-AVI | D74: =VLOOKUP('Storage '!A74,METADATA!A:G,7,FALSE) -> CBF-AVI | E74: 7 | F74: =VLOOKUP(D74,'Required trainings'!A:B,2,FALSE) -> 7 | G74: 2 | H74: 1 | I74: =IF(C74=D74,"no change","yes") -> no change
A75: Q0432 | B75: Carlo Alcoran Tenorio | C75: CM2 | D75: =VLOOKUP('Storage '!A75,METADATA!A:G,7,FALSE) -> CM2 | E75: 18 | F75: =VLOOKUP(D75,'Required trainings'!A:B,2,FALSE) -> 18 | G75: 4 | H75: 3 | I75: =IF(C75=D75,"no change","yes") -> no change
...

Sheet Required trainings
A1: Whereabouts | B1: EQUIPMENT TRAININGS Required
A2: MM office | B2: 0
A3: AMH | B3: 8
A4: CM1 | B4: 18
A5: PM1 | B5: 15
A6: DFWH | B6: 16
A7: Pantry | B7: 0
A8: Store room | B8: 0
A9: ULD Stands | B9: 3
A10: CBF-AVI | B10: 7
A11: Projects | B11: 0
A12: Oman | B12: 0
A13: KSA | B13: 0
... A30: Resigned | B30: 0

Sheet METADATA
A1: Emp. No. | B1: HIA ETAS | C1: Date of Joining | D1: Employee Name | E1: LSME designation | F1: DEPT | G1: Whereabouts | H1: Average Marks scored | I1: Equipment Trainings Required As per Facility | J1: SOP Trainings Required As per Facility | K1: Other Trainings Required | L1: COMPLETED EQUIPMENT TRAININGS | M1: COMPLETED SOP TRAININGS | N1: COMPLETED Other TRAININGS | O1: Pending Equipment Trainings | P1: Pending SOP Trainings | Q1: Pending Other Trainings
A2: G0010 | B2: C5883 | C2: 40909 | D2: Norbert Mueller | E2: Deputy Maintenance Manager | F2: Management | G2: MM office | I2: 0 | J2: 1 | K2: 1 | L2: 25 | M2: 51 | N2: 1 | O2: -25 | P2: -50 | Q2: 0
A3: Q0011 | B3: C5884 | C3: 39854 | D3: Mohamed Farkan Mohamed Sareek | E3: HR & Administration Officer | F3: Admin | G3: Admin office | I3: 0 | J3: 1 | K3: 1 | L3: 25 | M3: 51 | N3: 2 | O3: -25 | P3: -50 | Q3: -1
A4: Q0041 | B4: C5885 | C4: 40226 | D4: Destiny Emmanuel | E4: Maintenance Supervisor - Electrical | F4: AMH | G4: AMH | I4: 8 | J4: 3 | K4: 1 | L4: 25 | M4: 51 | N4: 2 | O4: -17 | P4: -48 | Q4: -1
A5: Q0042 | B5: C5886 | C5: 40226 | D5: Abdunaser Ahmed Aragaw | E5: Maintenance Supervisor - Electrical | F5: CARGO CM | G5: CM2 | I5: 18 | J5: 4 | K5: 3 | L5: 25 | M5: 51 | N5: 1 | O5: -7 | P5: -47 | Q5: 2
A6: Q0048 | B6: C5887 | C6: 40243 | D6: Rizardo Villalobos | E6: Maintenance Supervisor - Electrical | F6: CARGO CM | G6: CM4 | I6: 18 | J6: 4 | K6: 3 | L6: 25 | M6: 50 | N6: 2 | O6: -7 | P6: -46 | Q6: 1
A7: Q0055 | B7: C4273 | C7: 40307 | D7: Chidanand Bhaskara Chaithanya | E7: Maintenance Supervisor - Electrical | F7: DFWH | G7: QDF office | I7: 0 | J7: 3 | K7: 1 | L7: 25 | M7: 51 | N7: 2 | O7: -25 | P7: -48 | Q7: -1
A8: Q0058 | B8: C5888 | C8: 40319 | D8: Mahesh Ramachandra | E8: Maintenance Supervisor - Mechanical/ Acting DMM | F8: CARGO PM | G8: Technical support office | I8: 0 | J8: 3 | K8: 1 | L8: 25 | M8: 51 | N8: 2 | O8: -25 | P8: -48 | Q8: -1
A9: Q0065 | B9: C5889 | C9: 40362 | D9: Joel Cabrillos Misa | E9: Maintenance Supervisor - Electrical | F9: CARGO CM | G9: CM3 | I9: 18 | J9: 4 | K9: 3 | L9: 25 | M9: 51 | N9: 2 | O9: -7 | P9: -47 | Q9: 1
A10: Q0068 | B10: C5890 | C10: 40440 | D10: Ericson Murcillos Victorino | E10: Maintenance Supervisor - Electrical | F10: AMH | G10: AMH | I10: 26 | J10: 4 | K10: 3 | L10: 25 | M10: 51 | N10: 3 | O10: 1 | P10: -47 | Q10: 0
A11: Q0070 | B11: C5891 | C11: 40454 | D11: Fernan Dela Cruz | E11: Senior Maintenance Technician - Electrical/Acting PM Supervisor | F11: CARGO PM | G11: Technical support office | I11: 0 | J11: 3 | K11: 1 | L11: 25 | M11: 51 | N11: 2 | O11: -25 | P11: -48 | Q11: -1
A12: Q0077 | B12: C4274 | C12: 40575 | D12: Bindu Pillai | E12: IT Manager | F12: Management | G12: Technical support office | I12: 0 | J12: 1 | K12: 1 | L12: 25 | M12: 51 | N12: 1 | O12: -25 | P12: -50 | Q12: 0
A13: Q0082 | B13: C5892 | C13: 40625 | D13: Philippe Musangilay Kubula | E13: Senior Maintenance Technician - Electrical | F13: Admin | G13: Admin office | I13: 0 | J13: 1 | K13: 1 | L13: 25 | M13: 51 | N13: 1 | O13: -25 | P13: -50 | Q13: 0
... A15: Q0095 | B15: C5895 | C15: 40797 | D15: Jerry Arnejo Carandang | E15: Senior Maintenance Technician - Mechanical | F15: CARGO PM | G15: Technical support office | I15: 0 | J15: 3 | K15: 1 | L15: 25 | M15: 51 | N15: 3 | O15: -25 | P15: -48 | Q15: -2
A16: Q0098 | B16: C5896 | C16: 40822 | D16: Vicente Mendigorin Morelos | E16: Maintenance Technician - Mechanical | F16: Resigned | G16: Resigned | H16: 0.71228571 | I16: 18 | J16: 4 | K16: 3 | L16: 25 | M16: 51 | N16: 0 | O16: -7 | P16: -47 | Q16: 3
A17: Q0128 | B17: C5900 | C17: 41039 | D17: Sivagaran Ramanathan | E17: Maintenance Technician - Mechanical | F17: CARGO PM | G17: PM2 | H17: 0.5388 | I17: 15 | J17: 4 | K17: 3 | L17: 17 | M17: 49 | N17: 1 | O17: -2 | P17: -45 | Q17: 2
A18: Q0130 | B18: C01418 | C18: 41039 | D18: Cletes Albert Perera | E18: Maintenance Technician - Mechanical | F18: CARGO PM | G18: PM3 | H18: 0.35 | I18: 30 | J18: 4 | K18: 3 | L18: 12 | M18: 47 | N18: 2 | O18: 18 | P18: -43 | Q18: 1
A19: Q0132 | B19: C5903 | C19: 41039 | D19: Tharanga Pradeep Pathirannehelage | E19: Maintenance Technician - Mechanical | F19: CARGO CM | G19: CM2 | H19: 0.8941625 | I19: 18 | J19: 4 | K19: 3 | L19: 8 | M19: 36 | N19: 1 | O19: 10 | P19: -32 | Q19: 2
A20: Q0134 | B20: C5904 | C20: 41091 | D20: Pubudu Maduranga Hearth Ralalage | E20: Lead Maintenance Technician - Mechanical | F20: CARGO PM | G20: PM2 | H20: 0.90712 | I20: 15 | J20: 4 | K20: 3 | L20: 13 | M20: 48 | N20: 1 | O20: 2 | P20: -44 | Q20: 2
A21: Q0138 | B21: C5905 | C21: 41111 | D21: Joevergil Cajocson Dormitorio | E21: Senior Maintenance Technician - Electrical | F21: CARGO CM | G21: CM2 | I21: 18 | J21: 4 | K21: 3 | L21: 11 | M21: 35 | N21: 1 | O21: 7 | P21: -31 | Q21: 2
A22: Q0139 | B22: C5906 | C22: 41111 | D22: Ricky Catibog Katigbak | E22: Lead Maintenance Technician (Installation) | F22: Projects | G22: QNL | I22: 0 | L22: 25 | M22: 51 | N22: 0 | O22: -25 | P22: -51 | Q22: 0
A23: Q0149 | B23: C4278 | C23: 41181 | D23: Venice Mendova Jadloc | E23: Lead Maintenance Technician (Mechanical) | F23: Resigned | G23: Resigned | H23: 0.845 | I23: 16 | J23: 2 | K23: 1 | L23: 25 | M23: 51 | N23: 1 | O23: -9 | P23: -49 | Q23: 0
A24: Q0150 | B24: C5908 | C24: 41181 | D24: Lemuel Celeste Anacleto | E24: Senior Maintenance Technician - Mechanical | F24: CARGO CM | G24: CM3 | I24: 18 | J24: 4 | K24: 3 | L24: 23 | M24: 43 | N24: 2 | O24: -5 | P24: -39 | Q24: 1
A25: Q0158 | B25: C5913 | C25: 41181 | D25: Arnel Butiu Guevarra | E25: Lead Maintenance Technician (Electrical Installation) | F25: CARGO CM | G25: CM4 | H25: 0.895975 | I25: 18 | J25: 4 | K25: 3 | L25: 3 | M25: 48 | N25: 1 | O25: 15 | P25: -44 | Q25: 2
A26: Q0157 | B26: C03044 | C26: 42673 | D26: Edwin Balakid Tegli | E26: Lead Maintenance Technician - Electrical | F26: Resigned | G26: Resigned | H26: 0.88805 | I26: 8 | J26: 3 | K26: 1 | L26: 25 | M26: 51 | N26: 1 | O26: -17 | P26: -48 | Q26: 0
A27: Q0159 | B27: C4277 | C27: 41181 | D27: Jessie Jr. Alcuizar Hellera | E27: CMMS Senior TL | F27: Admin | G27: Admin office | I27: 0 | J27: 1 | K27: 1 | L27: 25 | M27: 51 | N27: 2 | O27: -25 | P27: -50 | Q27: -1
A28: Q0165 | B28: C5915 | C28: #N/A | D28: Noel Jarabe Riego | E28: Senior Maintenance Technician (Electrical Installation) | F28: Resigned | G28: Resigned | I28: 8 | L28: 25 | M28: 51 | N28: 1 | O28: -17 | P28: -51 | Q28: -1
A29: Q0170 | B29: C5917 | C29: 41245 | D29: Edilberto Angsioco | E29: Lead Maintenance Technician (Lift/Electrical) | F29: CARGO CM | G29: CM2 | H29: 0.85972667 | I29: 18 | J29: 4 | K29: 3 | L29: 8 | M29: 37 | N29: 1 | O29: 10 | P29: -33 | Q29: 2
A30: Q0185 | B30: C5921 | C30: 41365 | D30: Jose Dino Constantino | E30: Senior Maintenance Technician (Mechanical)/ Quality Assurance Supervisor | F30: Admin | G30: Admin office | I30: 0 | J30: 1 | K30: 1 | L30: 25 | M30: 51 | N30: 2 | O30: -25 | P30: -50 | Q30: -1
A31: Q0187 | B31: C5922 | C31: 41385 | D31: Regin Alis | E31: Senior Maintenance Technician - Mechanical | F31: CARGO CM | G31: CM4 | I31: 18 | J31: 4 | K31: 3 | L31: 18 | M31: 48 | N31: 1 | O31: 0 | P31: -44 | Q31: 2
A32: Q0188 | B32: C2561 | C32: 41396 | D32: Restito Fabic | E32: Project Supervisor - Mechanical | F32: Projects | G32: Admin office | I32: 0 | J32: 3 | K32: 1 | L32: 25 | M32: 51 | N32: 2 | O32: -25 | P32: -48 | Q32: -1
A33: Q0194 | B33: C5924 | C33: 41538 | D33: Kamalanathan Poopalapillai | E33: Driver | F33: Admin | G33: Pantry | I33: 0 | J33: 1 | K33: 1 | L33: 25 | M33: 51 | N33: 2 | O33: -25 | P33: -50 | Q33: -1
A34: Q0206 | B34: C5929 | C34: 41575 | D34: Anil Kumara | E34: Cleaner | F34: Admin | G34: Pantry | H34: 0 | I34: 0 | J34: 1 | K34: 1 | L34: 25 | M34: 51 | N34: 2 | O34: -25 | P34: -50 | Q34: -1
A35: Q0207 | B35: C5930 | C35: 41575 | D35: Lani Fernando Kachchakaduge | E35: Maintenance Technician - Mechanical | F35: CARGO PM | G35: PM2 | I35: 15 | J35: 4 | K35: 3 | L35: 12 | M35: 48 | N35: 1 | O35: 3 | P35: -44 | Q35: 2
A36: Q0208 | B36: C5931 | C36: 41575 | D36: Sampath Chamin | E36: Assistant Maintenance Technician | F36: CARGO PM | G36: PM3 | I36: 15 | J36: 4 | K36: 3 | L36: 18 | M36: 40 | N36: 2 | O36: -3 | P36: -36 | Q36: 1
A37: Q0216 | B37: C5932 | C37: 41576 | D37: Raymond Ian Montero | E37: Lead Storekeeper | F37: Admin | G37: Store room | I37: 0 | J37: 1 | K37: 1 | L37: 25 | M37: 51 | N37: 3 | O37: -25 | P37: -50 | Q37: -2
A38: Q0219 | B38: C5934 | C38: 41576 | D38: James Magnaye Catapia | E38: Lead Maintenance Technician (Electrical) | F38: CARGO CM | G38: CM3 | H38: 0.87505625 | I38: 36 | J38: 4 | K38: 3 | L38: 1 | M38: 38 | N38: 2 | O38: 35 | P38: -34 | Q38: 1
A39: Q0229 | B39: C5937 | C39: #N/A | D39: Marty Tolosa Ambas | E39: Lead Maintenance Technician (Mechanical) | F39: Resigned | G39: Resigned | H39: 0.73412222 | I39: 15 | J39: 4 | K39: 3 | L39: 25 | M39: 51 | N39: 2 | O39: -10 | P39: -47 | Q39: 1
A40: Q0234 | B40: C5940 | C40: 41602 | D40: Nove Manuel Menorisa Tagpuno | E40: Lead Maintenance Technician - Electrical | F40: CARGO CM | G40: CM1 | H40: 0.92405 | I40: 18 | J40: 4 | K40: 3 | L40: 16 | M40: 41 | N40: 2 | O40: 2 | P40: -37 | Q40: 1
A41: Q0235 | B41: C5941 | C41: 41602 | D41: Edgar Noceja | E41: Lead Maintenance Technician - Mechanical | F41: CARGO CM | G41: CM1 | H41: 0.92216154 | I41: 18 | J41: 4 | K41: 3 | L41: 15 | M41: 39 | N41: 2 | O41: 3 | P41: -35 | Q41: 1
...

Sheet Cargo Trainings
K2: Document No: | M2: LSME-TRN-FM-048
K3: Revision No: | M3: :00
A4: Emp. No. | B4: Employee Name | C4: Designation | D4: Team | E4: Count Of Trainings Expiring | F4: Date | G4: Stacker crane | H4: Date | I4: EWS EQ | J4: Date | K4: CS-H9-TV | L4: Date | M4: ULD&BB-TV | N4: Date | O4: BB TV 20FT | P4: Date | Q4: BB TV 15FT | R4: Date | S4: ULD TV 20FT | T4: Date | U4: ULD TV 15FT | V4: Date | W4: FMC-deck | X4: Date | Y4: Weight scales | Z4: Date | AA4: Tilting deck | AB4: Date | AC4: TT+RA | AD4: Date | AE4: CS-Hoist | AF4: Date | AG4: ULD Hoist | AH4: Date | AI4: Truck dock 15FT | AJ4: Date | AK4: Truck dock 20FT | AL4: Date | AM4: Softwares & Param. | AN4: Date | AO4: Control circuits | AP4: Date | AQ4: Cool Room | AR4: Date | AS4: Climate Control Center | AT4: Date | AU4: 3TIER RACK -G/H/A/303 | AV4: Date | AW4: 3TIER RACK -JBAY | AX4: Date | AY4: Non-powered roller Decks | AZ4: Date | BA4: Diagnosis Of Beckoff Module And Troubleshooting Guide | BB4: Date | BC4: Powered roller Decks2
A5: G0010 | B5: Norbert Mueller | C5: Deputy Maintenance Manager | D5: MM office | E5: 25 | G5: NOT DONE | I5: NOT DONE | K5: NOT DONE | M5: NOT DONE | O5: NOT DONE | Q5: NOT DONE | S5: NOT DONE | U5: NOT DONE | W5: NOT DONE | Y5: NOT DONE | AA5: NOT DONE | AC5: NOT DONE | AE5: NOT DONE | AG5: NOT DONE | AI5: NOT DONE | AK5: NOT DONE | AM5: NOT DONE | AO5: NOT DONE | AQ5: NOT DONE | AS5: NOT DONE | AU5: NOT DONE | AW5: NOT DONE | AY5: NOT DONE | BA5: NOT DONE | BC5: NOT DONE
A6: Q0011 | B6: Mohamed Farkan Mohamed Sareek | C6: HR & Administration Officer | D6: Admin office | E6: 25 | G6: NOT DONE | I6: NOT DONE | K6: NOT DONE | M6: NOT DONE | O6: NOT DONE | Q6: NOT DONE | S6: NOT DONE | U6: NOT DONE | W6: NOT DONE | Y6: NOT DONE | AA6: NOT DONE | AC6: NOT DONE | AE6: NOT DONE | AG6: NOT DONE | AI6: NOT DONE | AK6: NOT DONE | AM6: NOT DONE | AO6: NOT DONE | AQ6: NOT DONE | AS6: NOT DONE | AU6: NOT DONE | AW6: NOT DONE | AY6: NOT DONE | BA6: NOT DONE | BC6: NOT DONE
A7: Q0041 | B7: Destiny Emmanuel | C7: Maintenance Supervisor - Electrical | D7: AMH | E7: 25 | G7: NOT DONE | I7: NOT DONE | K7: NOT DONE | M7: NOT DONE | O7: NOT DONE | Q7: NOT DONE | S7: NOT DONE | U7: NOT DONE | W7: NOT DONE | Y7: NOT DONE | AA7: NOT DONE | AC7: NOT DONE | AE7: NOT DONE | AG7: NOT DONE | AI7: NOT DONE | AK7: NOT DONE | AM7: NOT DONE | AO7: NOT DONE | AQ7: NOT DONE | AS7: NOT DONE | AU7: NOT DONE | AW7: NOT DONE | AY7: NOT DONE | BA7: NOT DONE | BC7: NOT DONE
A8: Q0042 | B8: Abdunaser Ahmed Aragaw | C8: Maintenance Supervisor - Electrical | D8: CM2 | E8: 25 | G8: NOT DONE | I8: NOT DONE | K8: NOT DONE | M8: NOT DONE | O8: NOT DONE | Q8: NOT DONE | S8: NOT DONE | U8: NOT DONE | W8: NOT DONE | Y8: NOT DONE | AA8: NOT DONE | AC8: NOT DONE | AE8: NOT DONE | AG8: NOT DONE | AI8: NOT DONE | AK8: NOT DONE | AM8: NOT DONE | AO8: NOT DONE | AQ8: NOT DONE | AS8: NOT DONE | AU8: NOT DONE | AW8: NOT DONE | AY8: NOT DONE | BA8: NOT DONE | BC8: NOT DONE
A9: Q0048 | B9: Rizardo Villalobos | C9: Maintenance Supervisor - Electrical | D9: CM4 | E9: 25 | G9: NOT DONE | I9: NOT DONE | K9: NOT DONE | M9: NOT DONE | O9: NOT DONE | Q9: NOT DONE | S9: NOT DONE | U9: NOT DONE | W9: NOT DONE | Y9: NOT DONE | AA9: NOT DONE | AC9: NOT DONE | AE9: NOT DONE | AG9: NOT DONE | AI9: NOT DONE | AK9: NOT DONE | AM9: NOT DONE | AO9: NOT DONE | AQ9: NOT DONE | AS9: NOT DONE | AU9: NOT DONE | AW9: NOT DONE | AY9: NOT DONE | BA9: NOT DONE | BC9: NOT DONE
A10: Q0055 | B10: Chidanand Bhaskara Chaithanya | C10: Maintenance Supervisor - Electrical | D10: QDF office | E10: 25 | G10: NOT DONE | I10: NOT DONE | K10: NOT DONE | M10: NOT DONE | O10: NOT DONE | Q10: NOT DONE | S10: NOT DONE | U10: NOT DONE | W10: NOT DONE | Y10: NOT DONE | AA10: NOT DONE | AC10: NOT DONE | AE10: NOT DONE | AG10: NOT DONE | AI10: NOT DONE | AK10: NOT DONE | AM10: NOT DONE | AO10: NOT DONE | AQ10: NOT DONE | AS10: NOT DONE | AU10: NOT DONE | AW10: NOT DONE | AY10: NOT DONE | BA10: NOT DONE | BC10: NOT DONE
A11: Q0058 | B11: Mahesh Ramachandra | C11: Maintenance Supervisor - Mechanical/ Acting DMM | D11: Technical support office | E11: 25 | G11: NOT DONE | I11: NOT DONE | K11: NOT DONE | M11: NOT DONE | O11: NOT DONE | Q11: NOT DONE | S11: NOT DONE | U11: NOT DONE | W11: NOT DONE | Y11: NOT DONE | AA11: NOT DONE | AC11: NOT DONE | AE11: NOT DONE | AG11: NOT DONE | AI11: NOT DONE | AK11: NOT DONE | AM11: NOT DONE | AO11: NOT DONE | AQ11: NOT DONE | AS11: NOT DONE | AU11: NOT DONE | AW11: NOT DONE | AY11: NOT DONE | BA11: NOT DONE | BC11: NOT DONE
A12: Q0065 | B12: Joel Cabrillos Misa | C12: Maintenance Supervisor - Electrical | D12: CM3 | E12: 25 | G12: NOT DONE | I12: NOT DONE | K12: NOT DONE | M12: NOT DONE | O12: NOT DONE | Q12: NOT DONE | S12: NOT DONE | U12: NOT DONE | W12: NOT DONE | Y12: NOT DONE | AA12: NOT DONE | AC12: NOT DONE | AE12: NOT DONE | AG12: NOT DONE | AI12: NOT DONE | AK12: NOT DONE | AM12: NOT DONE | AO12: NOT DONE | AQ12: NOT DONE | AS12: NOT DONE | AU12: NOT DONE | AW12: NOT DONE | AY12: NOT DONE | BA12: NOT DONE | BC12: NOT DONE
A13: Q0068 | B13: Ericson Murcillos Victorino | C13: Maintenance Supervisor - Electrical | D13: AMH | E13: 25 | G13: NOT DONE | I13: NOT DONE | K13: NOT DONE | M13: NOT DONE | O13: NOT DONE | Q13: NOT DONE | S13: NOT DONE | U13: NOT DONE | W13: NOT DONE | Y13: NOT DONE | AA13: NOT DONE | AC13: NOT DONE | AE13: NOT DONE | AG13: NOT DONE | AI13: NOT DONE | AK13: NOT DONE | AM13: NOT DONE | AO13: NOT DONE | AQ13: NOT DONE | AS13: NOT DONE | AU13: NOT DONE | AW13: NOT DONE | AY13: NOT DONE | BA13: NOT DONE | BC13: NOT DONE
A14: Q0070 | B14: Fernan Dela Cruz | C14: Senior Maintenance Technician - Electrical/Acting PM Supervisor | D14: Technical support office | E14: 25 | G14: NOT DONE | I14: NOT DONE | K14: NOT DONE | M14: NOT DONE | O14: NOT DONE | Q14: NOT DONE | S14: NOT DONE | U14: NOT DONE | W14: NOT DONE | Y14: NOT DONE | AA14: NOT DONE | AC14: NOT DONE | AE14: NOT DONE | AG14: NOT DONE | AI14: NOT DONE | AK14: NOT DONE | AM14: NOT DONE | AO14: NOT DONE | AQ14: NOT DONE | AS14: NOT DONE | AU14: NOT DONE | AW14: NOT DONE | AY14: NOT DONE | BA14: NOT DONE | BC14: NOT DONE
A15: Q0077 | B15: Bindu Pillai | C15: IT Manager | D15: Technical support office | E15: 25 | G15: NOT DONE | I15: NOT DONE | K15: NOT DONE | M15: NOT DONE | O15: NOT DONE | Q15: NOT DONE | S15: NOT DONE | U15: NOT DONE | W15: NOT DONE | Y15: NOT DONE | AA15: NOT DONE | AC15: NOT DONE | AE15: NOT DONE | AG15: NOT DONE | AI15: NOT DONE | AK15: NOT DONE | AM15: NOT DONE | AO15: NOT DONE | AQ15: NOT DONE | AS15: NOT DONE | AU15: NOT DONE | AW15: NOT DONE | AY15: NOT DONE | BA15: NOT DONE | BC15: NOT DONE
A16: Q0082 | B16: Philippe Musangilay Kubula | C16: Senior Maintenance Technician - Electrical | D16: Admin office | E16: 25 | G16: NOT DONE | I16: NOT DONE | K16: NOT DONE | M16: NOT DONE | O16: NOT DONE | Q16: NOT DONE | S16: NOT DONE | U16: NOT DONE | W16: NOT DONE | Y16: NOT DONE | AA16: NOT DONE | AC16: NOT DONE | AE16: NOT DONE | AG16: NOT DONE | AI16: NOT DONE | AK16: NOT DONE | AM16: NOT DONE | AO16: NOT DONE | AQ16: NOT DONE | AS16: NOT DONE | AU16: NOT DONE | AW16: NOT DONE | AY16: NOT DONE | BA16: NOT DONE | BC16: NOT DONE
... A18: Q0095 | B18: Jerry Arnejo Carandang | C18: Senior Maintenance Technician - Mechanical | D18: Technical support office | E18: 25 | G18: NOT DONE | I18: NOT DONE | K18: NOT DONE | M18: NOT DONE | O18: NOT DONE | Q18: NOT DONE | S18: NOT DONE | U18: NOT DONE | W18: NOT DONE | Y18: NOT DONE | AA18: NOT DONE | AC18: NOT DONE | AE18: NOT DONE | AG18: NOT DONE | AI18: NOT DONE | AK18: NOT DONE | AM18: NOT DONE | AO18: NOT DONE | AQ18: NOT DONE | AS18: NOT DONE | AU18: NOT DONE | AW18: NOT DONE | AY18: NOT DONE | BA18: NOT DONE | BC18: NOT DONE
A19: Q0098 | B19: Vicente Mendigorin Morelos | C19: Maintenance Technician - Mechanical | D19: Resigned | E19: 25 | F19: 45538 | G19: DONE | H19: 45555 | I19: DONE | J19: 45523 | K19: DONE | L19: 45521 | M19: DONE | O19: NOT DONE | Q19: NOT DONE | S19: NOT DONE | U19: NOT DONE | V19: 45544 | W19: DONE | X19: 45516 | Y19: DONE | Z19: 45542 | AA19: DONE | AB19: 45557 | AC19: DONE | AD19: 45519 | AE19: DONE | AF19: 45535 | AG19: DONE | AH19: 45525 | AI19: DONE | AK19: NOT DONE | AM19: NOT DONE | AO19: NOT DONE | AP19: 45564 | AQ19: DONE | AR19: 45677 | AS19: DONE | AT19: 45676 | AU19: DONE | AV19: 45676 | AW19: DONE | AX19: 45676 | AY19: DONE | BA19: NOT DONE | BC19: NOT DONE
A20: Q0128 | B20: Sivagaran Ramanathan | C20: Maintenance Technician - Mechanical | D20: PM2 | E20: 17 | F20: 46132 | G20: DONE | H20: 46134 | I20: DONE | J20: 45634 | K20: DONE | L20: 46049 | M20: DONE | O20: NOT DONE | Q20: NOT DONE | S20: NOT DONE | U20: NOT DONE | V20: 45670 | W20: DONE | X20: 46049 | Y20: DONE | Z20: 46135 | AA20: DONE | AB20: 46050 | AC20: DONE | AD20: 46135 | AE20: DONE | AF20: 45788 | AG20: DONE | AH20: 45525 | AI20: DONE | AK20: NOT DONE | AL20: 45522 | AM20: DONE | AN20: 45522 | AO20: DONE | AP20: 46179 | AQ20: DONE | AR20: 45547 | AS20: DONE | AU20: NOT DONE | AW20: NOT DONE | AY20: NOT DONE | BA20: NOT DONE | BC20: NOT DONE
A21: Q0130 | B21: Cletes Albert Perera | C21: Maintenance Technician - Mechanical | D21: PM3 | E21: 12 | F21: 46135 | G21: DONE | H21: 45677 | I21: DONE | J21: 46135 | K21: DONE | L21: 45911 | M21: DONE | O21: NOT DONE | Q21: NOT DONE | S21: NOT DONE | U21: NOT DONE | V21: 46138 | W21: DONE | X21: 45910 | Y21: DONE | Z21: 46138 | AA21: DONE | AB21: 46135 | AC21: DONE | AD21: 46135 | AE21: DONE | AF21: 46138 | AG21: DONE | AH21: 46138 | AI21: DONE | AK21: NOT DONE | AM21: NOT DONE | AO21: NOT DONE | AP21: 46138 | AQ21: DONE | AR21: 46138 | AS21: DONE | AU21: NOT DONE | AW21: NOT DONE | AY21: NOT DONE | BA21: NOT DONE | BB21: 46138 | BC21: DONE
A22: Q0132 | B22: Tharanga Pradeep Pathirannehelage | C22: Maintenance Technician - Mechanical | D22: CM2 | E22: 8 | F22: 46295 | G22: DONE | H22: 45569 | I22: DONE | J22: 46252 | K22: DONE | L22: 45699 | M22: DONE | N22: 46253 | O22: DONE | P22: 46253 | Q22: DONE | S22: NOT DONE | U22: NOT DONE | V22: 46313 | W22: DONE | X22: 46253 | Y22: DONE | Z22: 46312 | AA22: DONE | AB22: 46283 | AC22: DONE | AD22: 46253 | AE22: DONE | AF22: 46273 | AG22: DONE | AH22: 45596 | AI22: DONE | AK22: NOT DONE | AL22: 46313 | AM22: DONE | AN22: 46146 | AO22: DONE | AP22: 46254 | AQ22: DONE | AR22: 46295 | AS22: DONE | AT22: 46146 | AU22: DONE | AV22: 46146 | AW22: DONE | AX22: 45689 | AY22: DONE | BA22: NOT DONE | BB22: 46274 | BC22: DONE
A23: Q0134 | B23: Pubudu Maduranga Hearth Ralalage | C23: Lead Maintenance Technician - Mechanical | D23: PM2 | E23: 13 | F23: 46132 | G23: DONE | H23: 46133 | I23: DONE | J23: 46133 | K23: DONE | L23: 46134 | M23: DONE | O23: NOT DONE | Q23: NOT DONE | S23: NOT DONE | U23: NOT DONE | V23: 46134 | W23: DONE | X23: 46049 | Y23: DONE | Z23: 45792 | AA23: DONE | AB23: 46138 | AC23: DONE | AD23: 46138 | AE23: DONE | AF23: 46139 | AG23: DONE | AH23: 46139 | AI23: DONE | AK23: NOT DONE | AL23: 45522 | AM23: DONE | AN23: 45522 | AO23: DONE | AP23: 46139 | AQ23: DONE | AR23: 46140 | AS23: DONE | AU23: NOT DONE | AW23: NOT DONE | AY23: NOT DONE | BA23: NOT DONE | BC23: NOT DONE
A24: Q0138 | B24: Joevergil Cajocson Dormitorio | C24: Senior Maintenance Technician - Electrical | D24: CM2 | E24: 11 | F24: 46295 | G24: DONE | H24: 45562 | I24: DONE | J24: 46252 | K24: DONE | L24: 45545 | M24: DONE | N24: 46253 | O24: DONE | P24: 46253 | Q24: DONE | S24: NOT DONE | U24: NOT DONE | V24: 45593 | W24: DONE | X24: 46253 | Y24: DONE | Z24: 45594 | AA24: DONE | AB24: 46283 | AC24: DONE | AD24: 46253 | AE24: DONE | AF24: 46273 | AG24: DONE | AH24: 45633 | AI24: DONE | AK24: NOT DONE | AL24: 45595 | AM24: DONE | AN24: 46146 | AO24: DONE | AP24: 46254 | AQ24: DONE | AR24: 46295 | AS24: DONE | AT24: 46146 | AU24: DONE | AV24: 46146 | AW24: DONE | AX24: 45689 | AY24: DONE | BA24: NOT DONE | BB24: 46274 | BC24: DONE
A25: Q0139 | B25: Ricky Catibog Katigbak | C25: Lead Maintenance Technician (Installation) | D25: QNL | E25: 25 | G25: NOT DONE | I25: NOT DONE | K25: NOT DONE | M25: NOT DONE | O25: NOT DONE | Q25: NOT DONE | S25: NOT DONE | U25: NOT DONE | W25: NOT DONE | Y25: NOT DONE | AA25: NOT DONE | AC25: NOT DONE | AE25: NOT DONE | AG25: NOT DONE | AI25: NOT DONE | AK25: NOT DONE | AM25: NOT DONE | AO25: NOT DONE | AQ25: NOT DONE | AS25: NOT DONE | AU25: NOT DONE | AW25: NOT DONE | AY25: NOT DONE | BA25: NOT DONE | BC25: NOT DONE
A26: Q0149 | B26: Venice Mendova Jadloc | C26: Lead Maintenance Technician (Mechanical) | D26: Resigned | E26: 25 | G26: NOT DONE | I26: NOT DONE | K26: NOT DONE | M26: NOT DONE | O26: NOT DONE | Q26: NOT DONE | S26: NOT DONE | U26: NOT DONE | W26: NOT DONE | Y26: NOT DONE | AA26: NOT DONE | AC26: NOT DONE | AE26: NOT DONE | AG26: NOT DONE | AI26: NOT DONE | AK26: NOT DONE | AM26: NOT DONE | AO26: NOT DONE | AQ26: NOT DONE | AS26: NOT DONE | AU26: NOT DONE | AW26: NOT DONE | AY26: NOT DONE | BA26: NOT DONE | BC26: NOT DONE
A27: Q0150 | B27: Lemuel Celeste Anacleto | C27: Senior Maintenance Technician - Mechanical | D27: CM3 | E27: 23 | F27: 45864 | G27: DONE | I27: NOT DONE | K27: NOT DONE | M27: NOT DONE | O27: NOT DONE | Q27: NOT DONE | S27: NOT DONE | U27: NOT DONE | W27: NOT DONE | Y27: NOT DONE | AA27: NOT DONE | AC27: NOT DONE | AE27: NOT DONE | AF27: 45950 | AG27: DONE | AI27: NOT DONE | AK27: NOT DONE | AM27: NOT DONE | AO27: NOT DONE | AQ27: NOT DONE | AS27: NOT DONE | AU27: NOT DONE | AW27: NOT DONE | AY27: NOT DONE | BA27: NOT DONE | BC27: NOT DONE
A28: Q0157 | B28: Edwin Balakid Tegli | C28: Lead Maintenance Technician - Electrical | D28: Resigned | E28: 25 | G28: NOT DONE | I28: NOT DONE | K28: NOT DONE | M28: NOT DONE | O28: NOT DONE | Q28: NOT DONE | S28: NOT DONE | U28: NOT DONE | W28: NOT DONE | Y28: DONE | AA28: NOT DONE | AC28: NOT DONE | AE28: NOT DONE | AG28: NOT DONE | AI28: NOT DONE | AK28: NOT DONE | AM28: NOT DONE | AO28: NOT DONE | AQ28: NOT DONE | AS28: NOT DONE | AU28: NOT DONE | AW28: NOT DONE | AY28: NOT DONE | BA28: NOT DONE | BC28: NOT DONE
A29: Q0158 | B29: Arnel Butiu Guevarra | C29: Lead Maintenance Technician (Electrical Installation) | D29: CM4 | E29: 3 | F29: 45862 | G29: DONE | H29: 46311 | I29: DONE | J29: 46184 | K29: DONE | L29: 45521 | M29: DONE | N29: 46311 | O29: DONE | P29: 46311 | Q29: DONE | R29: 46311 | S29: DONE | T29: 46311 | U29: DONE | V29: 46312 | W29: DONE | X29: 46121 | Y29: DONE | Z29: 46312 | AA29: DONE | AB29: 46312 | AC29: DONE | AD29: 45884 | AE29: DONE | AF29: 46315 | AG29: DONE | AH29: 46318 | AI29: DONE | AJ29: 46317 | AK29: DONE | AM29: NOT DONE | AN29: 46072 | AO29: DONE | AP29: 46317 | AQ29: DONE | AR29: 45852 | AS29: DONE | AT29: 45856 | AU29: DONE | AV29: 45852 | AW29: DONE | AX29: 45878 | AY29: DONE | BA29: NOT DONE | BB29: 46071 | BC29: DONE
A30: Q0159 | B30: Jessie Jr. Alcuizar Hellera | C30: CMMS Senior TL | D30: Admin office | E30: 25 | G30: NOT DONE | I30: NOT DONE | K30: NOT DONE | M30: NOT DONE | O30: NOT DONE | Q30: NOT DONE | S30: NOT DONE | U30: NOT DONE | W30: NOT DONE | Y30: NOT DONE | AA30: NOT DONE | AC30: NOT DONE | AE30: NOT DONE | AG30: NOT DONE | AI30: NOT DONE | AK30: NOT DONE | AM30: NOT DONE | AO30: NOT DONE | AQ30: NOT DONE | AS30: NOT DONE | AU30: NOT DONE | AW30: NOT DONE | AY30: NOT DONE | BA30: NOT DONE | BC30: NOT DONE
A31: Q0165 | B31: Noel Jarabe Riego | C31: Senior Maintenance Technician (Electrical Installation) | D31: Resigned | E31: 25 | G31: NOT DONE | I31: NOT DONE | K31: NOT DONE | M31: NOT DONE | O31: NOT DONE | Q31: NOT DONE | S31: NOT DONE | U31: NOT DONE | W31: NOT DONE | Y31: NOT DONE | AA31: NOT DONE | AC31: NOT DONE | AE31: NOT DONE | AG31: NOT DONE | AI31: NOT DONE | AK31: NOT DONE | AM31: NOT DONE | AO31: NOT DONE | AQ31: NOT DONE | AS31: NOT DONE | AU31: NOT DONE | AW31: NOT DONE | AY31: NOT DONE | BA31: NOT DONE | BC31: NOT DONE
A32: Q0170 | B32: Edilberto Angsioco | C32: Lead Maintenance Technician (Lift/Electrical) | D32: CM2 | E32: 8 | F32: 46295 | G32: DONE | H32: 45569 | I32: DONE | J32: 46252 | K32: DONE | L32: 45545 | M32: DONE | N32: 46253 | O32: DONE | P32: 46253 | Q32: DONE | S32: NOT DONE | U32: NOT DONE | V32: 46313 | W32: DONE | X32: 46253 | Y32: DONE | Z32: 46312 | AA32: DONE | AB32: 46283 | AC32: DONE | AD32: 46253 | AE32: DONE | AF32: 46273 | AG32: DONE | AH32: 45633 | AI32: DONE | AK32: NOT DONE | AL32: 46313 | AM32: DONE | AN32: 46146 | AO32: DONE | AP32: 46254 | AQ32: DONE | AR32: 46295 | AS32: DONE | AT32: 46146 | AU32: DONE | AV32: 46146 | AW32: DONE | AX32: 45689 | AY32: DONE | BA32: NOT DONE | BB32: 46274 | BC32: DONE
A33: Q0185 | B33: Jose Dino Constantino | C33: Senior Maintenance Technician (Mechanical)/ Quality Assurance Supervisor | D33: Admin office | E33: 25 | G33: NOT DONE | I33: NOT DONE | K33: NOT DONE | M33: NOT DONE | O33: NOT DONE | Q33: NOT DONE | S33: NOT DONE | U33: NOT DONE | W33: NOT DONE | Y33: NOT DONE | AA33: NOT DONE | AC33: NOT DONE | AE33: NOT DONE | AG33: NOT DONE | AI33: NOT DONE | AK33: NOT DONE | AM33: NOT DONE | AO33: NOT DONE | AQ33: NOT DONE | AS33: NOT DONE | AU33: NOT DONE | AW33: NOT DONE | AY33: NOT DONE | BA33: NOT DONE | BC33: NOT DONE
A34: Q0187 | B34: Regin Alis | C34: Senior Maintenance Technician - Mechanical | D34: CM4 | E34: 18 | G34: NOT DONE | I34: NOT DONE | J34: 46184 | K34: DONE | M34: NOT DONE | O34: NOT DONE | Q34: NOT DONE | S34: NOT DONE | U34: NOT DONE | V34: 46312 | W34: DONE | X34: 46121 | Y34: DONE | Z34: 46312 | AA34: DONE | AB34: 46312 | AC34: DONE | AE34: NOT DONE | AG34: NOT DONE | AI34: NOT DONE | AK34: NOT DONE | AM34: NOT DONE | AN34: 46072 | AO34: DONE | AQ34: NOT DONE | AS34: NOT DONE | AU34: NOT DONE | AW34: NOT DONE | AY34: NOT DONE | BA34: NOT DONE | BB34: 46071 | BC34: DONE
A35: Q0188 | B35: Restito Fabic | C35: Project Supervisor - Mechanical | D35: Admin office | E35: 25 | G35: NOT DONE | I35: NOT DONE | K35: NOT DONE | M35: NOT DONE | O35: NOT DONE | Q35: NOT DONE | S35: NOT DONE | U35: NOT DONE | W35: NOT DONE | Y35: NOT DONE | AA35: NOT DONE | AC35: NOT DONE | AE35: NOT DONE | AG35: NOT DONE | AI35: NOT DONE | AK35: NOT DONE | AM35: NOT DONE | AO35: NOT DONE | AQ35: NOT DONE | AS35: NOT DONE | AU35: NOT DONE | AW35: NOT DONE | AY35: NOT DONE | BA35: NOT DONE | BC35: NOT DONE
A36: Q0194 | B36: Kamalanathan Poopalapillai | C36: Driver | D36: Pantry | E36: 25 | G36: NOT DONE | I36: NOT DONE | K36: NOT DONE | M36: NOT DONE | O36: NOT DONE | Q36: NOT DONE | S36: NOT DONE | U36: NOT DONE | W36: NOT DONE | Y36: NOT DONE | AA36: NOT DONE | AC36: NOT DONE | AE36: NOT DONE | AG36: NOT DONE | AI36: NOT DONE | AK36: NOT DONE | AM36: NOT DONE | AO36: NOT DONE | AQ36: NOT DONE | AS36: NOT DONE | AU36: NOT DONE | AW36: NOT DONE | AY36: NOT DONE | BA36: NOT DONE | BC36: NOT DONE
A37: Q0206 | B37: Anil Kumara | C37: Cleaner | D37: Pantry | E37: 25 | G37: NOT DONE | I37: NOT DONE | K37: NOT DONE | M37: NOT DONE | O37: NOT DONE | Q37: NOT DONE | S37: NOT DONE | U37: NOT DONE | W37: NOT DONE | Y37: NOT DONE | AA37: NOT DONE | AC37: NOT DONE | AE37: NOT DONE | AG37: NOT DONE | AI37: NOT DONE | AK37: NOT DONE | AM37: NOT DONE | AO37: NOT DONE | AQ37: NOT DONE | AS37: NOT DONE | AU37: NOT DONE | AW37: NOT DONE | AY37: NOT DONE | BA37: NOT DONE | BC37: NOT DONE
A38: Q0207 | B38: Lani Fernando Kachchakaduge | C38: Maintenance Technician - Mechanical | D38: PM2 | E38: 12 | F38: 46132 | G38: DONE | H38: 46133 | I38: DONE | J38: 46133 | K38: DONE | L38: 46134 | M38: DONE | O38: NOT DONE | Q38: NOT DONE | S38: NOT DONE | U38: NOT DONE | V38: 46134 | W38: DONE | X38: 46135 | Y38: DONE | Z38: 46135 | AA38: DONE | AB38: 46138 | AC38: DONE | AD38: 46138 | AE38: DONE | AF38: 46139 | AG38: DONE | AH38: 46139 | AI38: DONE | AK38: NOT DONE | AL38: 45522 | AM38: DONE | AN38: 45522 | AO38: DONE | AP38: 46139 | AQ38: DONE | AR38: 46140 | AS38: DONE | AU38: NOT DONE | AW38: NOT DONE | AY38: NOT DONE | BA38: NOT DONE | BC38: NOT DONE
A39: Q0208 | B39: Sampath Chamin | C39: Assistant Maintenance Technician | D39: PM3 | E39: 18 | F39: 45613 | G39: DONE | H39: 46196 | I39: DONE | J39: 46196 | K39: DONE | L39: 45718 | M39: DONE | O39: NOT DONE | Q39: NOT DONE | S39: NOT DONE | U39: NOT DONE | V39: 45670 | W39: DONE | X39: 45712 | Y39: DONE | Z39: 46135 | AA39: DONE | AB39: 45690 | AC39: DONE | AD39: 45728 | AE39: DONE | AF39: 45587 | AG39: DONE | AH39: 46139 | AI39: DONE | AK39: NOT DONE | AL39: 45536 | AM39: DONE | AN39: 46222 | AO39: DONE | AP39: 45893 | AQ39: DONE | AR39: 46267 | AS39: DONE | AU39: NOT DONE | AV39: 45582 | AW39: DONE | AY39: NOT DONE | BA39: NOT DONE | BC39: NOT DONE
A40: Q0216 | B40: Raymond Ian Montero | C40: Lead Storekeeper | D40: Store room | E40: 25 | G40: NOT DONE | I40: NOT DONE | K40: NOT DONE | M40: NOT DONE | O40: NOT DONE | Q40: NOT DONE | S40: NOT DONE | U40: NOT DONE | W40: NOT DONE | Y40: NOT DONE | AA40: NOT DONE | AC40: NOT DONE | AE40: NOT DONE | AG40: NOT DONE | AI40: NOT DONE | AK40: NOT DONE | AM40: NOT DONE | AO40: NOT DONE | AQ40: NOT DONE | AS40: NOT DONE | AU40: NOT DONE | AW40: NOT DONE | AY40: NOT DONE | BA40: NOT DONE | BC40: NOT DONE
A41: Q0219 | B41: James Magnaye Catapia | C41: Lead Maintenance Technician (Electrical) | D41: CM3 | E41: 1 | F41: 46304 | G41: DONE | H41: 46311 | I41: DONE | J41: 46310 | K41: DONE | L41: 45938 | M41: DONE | N41: 46272 | O41: DONE | P41: 46272 | Q41: DONE | R41: 46272 | S41: DONE | T41: 46272 | U41: DONE | V41: 45948 | W41: DONE | X41: 46312 | Y41: DONE | Z41: 46311 | AA41: DONE | AB41: 46307 | AC41: DONE | AD41: 46304 | AE41: DONE | AF41: 46311 | AG41: DONE | AH41: 46310 | AI41: DONE | AJ41: 46310 | AK41: DONE | AL41: 45596 | AM41: DONE | AN41: 46312 | AO41: DONE | AP41: 45941 | AQ41: DONE | AR41: 46312 | AS41: DONE | AT41: 46270 | AU41: DONE | AV41: 46270 | AW41: DONE | AX41: 46312 | AY41: DONE | AZ41: 45951 | BA41: DONE | BB41: 46311 | BC41: DONE
A42: Q0229 | B42: Marty Tolosa Ambas | C42: Lead Maintenance Technician (Mechanical) | D42: Resigned | E42: 25 | F42: 45657 | G42: DONE | H42: 45430 | I42: DONE | J42: 45713 | K42: DONE | L42: 45550 | M42: DONE | O42: NOT DONE | Q42: NOT DONE | S42: NOT DONE | U42: NOT DONE | W42: NOT DONE | X42: 45712 | Y42: DONE | Z42: 45579 | AA42: DONE | AC42: NOT DONE | AE42: NOT DONE | AF42: 45678 | AG42: DONE | AH42: 45714 | AI42: DONE | AK42: NOT DONE | AL42: 45536 | AM42: DONE | AN42: 45586 | AO42: DONE | AP42: 45441 | AQ42: DONE | AR42: 45544 | AS42: DONE | AU42: NOT DONE | AW42: NOT DONE | AY42: NOT DONE | BA42: NOT DONE | BC42: NOT DONE
...

Sheet DFW Trainings
A1: Emp. No. | B1: Employee Name | C1: TEAM | D1: Count Of Trainings From June | E1: Count Of Trainings | F1: Date | G1: Reach Truck R16 | H1: Date | I1: VNA Truck-K | J1: Date | K1: Stretch Wrapper | L1: Date | M1: Counter Balance Truck E-15 | N1: Date | O1: Order Picker | P1: Date | Q1: Bin Conveyor System | R1: Date | S1: Pallet Conveyor System | T1: Date | U1: Pallet Stacker L-14 | V1: Date | W1: Bin Hoist S-Type | X1: Date | Y1: Low Lift Truck T30 | Z1: Date | AA1: Bizerba Weight | AB1: Date | AC1: ASRS Stacker Crane | AD1: Date | AE1: Pallet Hoist | AF1: Date | AG1: Linde Software and ELOKON | AH1: Date | AI1: MHE Battery & Chargers | AJ1: Date | AK1: Stretch Wrapper Parameters | AL1: Date | AM1: Maintenance Work Guide For New Member | AN1: Date | AO1: MFC-EDS Operational Training Manual
A2: Q0055 | B2: Chidanand Bhaskara Chaithanya | C2: QDF office | D2: 20 | E2: 0 | G2: NOT DONE | I2: NOT DONE | K2: NOT DONE | M2: NOT DONE | O2: NOT DONE | Q2: NOT DONE | S2: NOT DONE | U2: NOT DONE | W2: NOT DONE | Y2: NOT DONE | AA2: NOT DONE | AC2: NOT DONE | AE2: NOT DONE | AG2: NOT DONE | AI2: NOT DONE | AK2: NOT DONE
A3: Q0149 | B3: Venice Mendova Jadloc | C3: Resigned | D3: 17 | E3: 16 | F3: 45589 | G3: DONE | H3: 45508 | I3: DONE | J3: 45511 | K3: DONE | L3: 45545 | M3: DONE | N3: 45539 | O3: DONE | P3: 45859 | Q3: DONE | R3: 45593 | S3: DONE | T3: 45560 | U3: DONE | V3: 45564 | W3: DONE | X3: 45586 | Y3: DONE | Z3: 45544 | AA3: DONE | AB3: 45578 | AC3: DONE | AD3: 45581 | AE3: DONE | AF3: 45593 | AG3: DONE | AH3: 45592 | AI3: DONE | AJ3: 45557 | AK3: DONE | AM3: NOT DONE | AO3: NOT DONE
A4: Q0274 | B4: Renato Dimalanta Canlas | C4: DFWH | D4: 15 | E4: 16 | F4: 45589 | G4: DONE | H4: 46243 | I4: DONE | J4: 46243 | K4: DONE | L4: 45550 | M4: DONE | N4: 45539 | O4: DONE | P4: 45875 | Q4: DONE | R4: 45593 | S4: DONE | T4: 45572 | U4: DONE | V4: 45552 | W4: DONE | X4: 45589 | Y4: DONE | Z4: 45551 | AA4: DONE | AB4: 45575 | AC4: DONE | AD4: 45579 | AE4: DONE | AF4: 45593 | AG4: DONE | AH4: 45592 | AI4: DONE | AJ4: 45549 | AK4: DONE | AM4: NOT DONE | AO4: NOT DONE
A5: Q0275 | B5: Ruben Dela Cruz Malabo | C5: DFWH | D5: 17 | E5: 16 | F5: 45587 | G5: DONE | H5: 45508 | I5: DONE | J5: 45511 | K5: DONE | L5: 45545 | M5: DONE | N5: 45547 | O5: DONE | P5: 45859 | Q5: DONE | R5: 45587 | S5: DONE | T5: 45566 | U5: DONE | V5: 45564 | W5: DONE | X5: 45586 | Y5: DONE | Z5: 45544 | AA5: DONE | AB5: 45585 | AC5: DONE | AD5: 45588 | AE5: DONE | AF5: 45593 | AG5: DONE | AH5: 45592 | AI5: DONE | AJ5: 45550 | AK5: DONE | AM5: NOT DONE | AO5: NOT DONE
A6: Q0281 | B6: Billy Jim Morelos | C6: DFWH | D6: 1 | E6: 16 | F6: 46312 | G6: DONE | H6: 46250 | I6: DONE | J6: 46250 | K6: DONE | L6: 46279 | M6: DONE | N6: 46289 | O6: DONE | P6: 45859 | Q6: DONE | R6: 46310 | S6: DONE | T6: 46289 | U6: DONE | V6: 46289 | W6: DONE | X6: 46316 | Y6: DONE | Z6: 46310 | AA6: DONE | AB6: 46299 | AC6: DONE | AD6: 46312 | AE6: DONE | AF6: 46049 | AG6: DONE | AH6: 46316 | AI6: DONE | AJ6: 46279 | AK6: DONE | AM6: NOT DONE | AN6: 46316 | AO6: DONE
A7: Q0301 | B7: Rogelio Reyes Gomez Jr. | C7: DFWH | D7: 7 | E7: 15 | F7: 45946 | G7: DONE | H7: 45946 | I7: DONE | J7: 46284 | K7: DONE | L7: 46284 | M7: DONE | N7: 46273 | O7: DONE | P7: 45865 | Q7: DONE | R7: 45676 | S7: DONE | T7: 45713 | U7: DONE | V7: 45693 | W7: DONE | X7: 45729 | Y7: DONE | Z7: 46284 | AA7: DONE | AB7: 46307 | AC7: DONE | AE7: NOT DONE | AF7: 45952 | AG7: DONE | AH7: 45853 | AI7: DONE | AJ7: 46284 | AK7: DONE | AM7: NOT DONE | AO7: NOT DONE
A8: Q0329 | B8: Nhuel Caguicla Landicho | C8: QDF office | D8: 17 | E8: 1 | G8: NOT DONE | I8: NOT DONE | K8: NOT DONE | M8: NOT DONE | O8: NOT DONE | Q8: NOT DONE | S8: NOT DONE | U8: NOT DONE | W8: NOT DONE | Y8: NOT DONE | AA8: NOT DONE | AC8: NOT DONE | AD8: 45951 | AE8: DONE | AG8: NOT DONE | AI8: NOT DONE | AK8: NOT DONE | AM8: NOT DONE | AO8: NOT DONE
A9: Q0429 | B9: Elecer Hernandez Llamoso | C9: DFWH | D9: 18 | E9: 16 | F9: 45589 | G9: DONE | H9: 45508 | I9: DONE | J9: 45511 | K9: DONE | L9: 45545 | M9: DONE | N9: 45539 | O9: DONE | P9: 45546 | Q9: DONE | R9: 45587 | S9: DONE | T9: 45560 | U9: DONE | V9: 45564 | W9: DONE | X9: 45586 | Y9: DONE | Z9: 45544 | AA9: DONE | AB9: 45575 | AC9: DONE | AD9: 45579 | AE9: DONE | AF9: 45593 | AG9: DONE | AH9: 45592 | AI9: DONE | AJ9: 45523 | AK9: DONE | AM9: NOT DONE | AO9: NOT DONE
A10: Q0430 | B10: Elesor JR Cas Frondozo | C10: CBF-AVI | D10: 32 | E10: 1 | G10: NOT DONE | I10: NOT DONE | AB10: 46012 | AC10: DONE
A11: Q0489 | B11: Crisfo Lo Nibal | C11: DFWH | D11: 4 | E11: 16 | F11: 46314 | G11: DONE | H11: 46242 | I11: DONE | J11: 46243 | K11: DONE | L11: 46295 | M11: DONE | N11: 46274 | O11: DONE | P11: 46295 | Q11: DONE | R11: 46301 | S11: DONE | T11: 45547 | U11: DONE | V11: 46295 | W11: DONE | X11: 46316 | Y11: DONE | Z11: 46295 | AA11: DONE | AB11: 45579 | AC11: DONE | AD11: 46314 | AE11: DONE | AF11: 45589 | AG11: DONE | AH11: 46316 | AI11: DONE | AJ11: 46243 | AK11: DONE | AM11: NOT DONE | AN11: 46316 | AO11: DONE
A12: Q0499 | B12: Nino Vercide Arda | C12: DFWH | D12: 2 | E12: 16 | F12: 46312 | G12: DONE | H12: 46287 | I12: DONE | J12: 46244 | K12: DONE | L12: 46284 | M12: DONE | N12: 46273 | O12: DONE | P12: 45859 | Q12: DONE | R12: 46314 | S12: DONE | T12: 46245 | U12: DONE | V12: 46287 | W12: DONE | X12: 46321 | Y12: DONE | Z12: 46284 | AA12: DONE | AB12: 46299 | AC12: DONE | AD12: 46312 | AE12: DONE | AF12: 45579 | AG12: DONE | AH12: 46314 | AI12: DONE | AJ12: 46244 | AK12: DONE | AM12: NOT DONE | AN12: 46321 | AO12: DONE
A13: Q0503 | B13: Jeffery Manarpaac Urolaza | C13: Resigned | D13: 10 | E13: 16 | F13: 45782 | G13: DONE | H13: 45771 | I13: DONE | J13: 45782 | K13: DONE | L13: 45789 | M13: DONE | N13: 45865 | O13: DONE | P13: 45819 | Q13: DONE | R13: 45818 | S13: DONE | T13: 45770 | U13: DONE | V13: 45852 | W13: DONE | X13: 45826 | Y13: DONE | Z13: 45823 | AA13: DONE | AB13: 45833 | AC13: DONE | AD13: 45851 | AE13: DONE | AF13: 45824 | AG13: DONE | AH13: 45853 | AI13: DONE | AJ13: 45781 | AK13: DONE | AL13: 45754 | AM13: DONE | AN13: 45866 | AO13: DONE
A14: Q0530 | B14: Erick Omondi Okoyo | C14: CBF-AVI | D14: 10 | E14: 16 | F14: 46162 | G14: DONE | H14: 46159 | I14: DONE | J14: 45686 | K14: DONE | L14: 45714 | M14: DONE | N14: 45725 | O14: DONE | P14: 46168 | Q14: DONE | R14: 45670 | S14: DONE | T14: 45713 | U14: DONE | V14: 45693 | W14: DONE | X14: 45729 | Y14: DONE | Z14: 46167 | AA14: DONE | AB14: 46012 | AC14: DONE | AD14: 45692 | AE14: DONE | AF14: 46167 | AG14: DONE | AH14: 45732 | AI14: DONE | AJ14: 46167 | AK14: DONE | AM14: NOT DONE | AN14: 46168 | AO14: DONE
A15: Q0534 | B15: Naser Qasim Mohammad Alhaj Ahmed | C15: QDF office | D15: 18 | E15: 0 | G15: NOT DONE | I15: NOT DONE | K15: NOT DONE | M15: NOT DONE | O15: NOT DONE | Q15: NOT DONE | S15: NOT DONE | U15: NOT DONE | W15: NOT DONE | Y15: NOT DONE | AA15: NOT DONE | AC15: NOT DONE | AE15: NOT DONE | AG15: NOT DONE | AI15: NOT DONE | AK15: NOT DONE | AM15: NOT DONE | AO15: NOT DONE
A16: Q0542 | B16: Hernan John Baguion Murcillos | C16: CBF-AVI | D16: 8 | E16: 12 | F16: 46279 | G16: DONE | H16: 46013 | I16: DONE | J16: 46273 | K16: DONE | L16: 46279 | M16: DONE | N16: 46274 | O16: DONE | P16: 46280 | Q16: DONE | R16: 46273 | T16: 46273 | V16: 46280 | W16: DONE | X16: 46274 | Y16: DONE | Z16: 46280 | AA16: DONE | AB16: 46301 | AC16: DONE | AD16: 46273 | AF16: 46282 | AG16: DONE | AH16: 46281 | AI16: DONE | AJ16: 46273
A17: Q0575 | B17: Jacky Chan Nava Gastardo | C17: DFWH | D17: 2 | E17: 16 | F17: 46312 | G17: DONE | H17: 46242 | I17: DONE | J17: 46162 | K17: DONE | L17: 46288 | M17: DONE | N17: 46273 | O17: DONE | P17: 45859 | Q17: DONE | R17: 46187 | S17: DONE | T17: 46168 | U17: DONE | V17: 46288 | W17: DONE | X17: 46168 | Y17: DONE | Z17: 46288 | AA17: DONE | AB17: 46301 | AC17: DONE | AD17: 46312 | AE17: DONE | AF17: 45579 | AG17: DONE | AH17: 46313 | AI17: DONE | AJ17: 46243 | AK17: DONE | AM17: NOT DONE | AN17: 46188 | AO17: DONE
A18: Q0582 | B18: Mohomed Minnas Mohomed Ramees | C18: CBF-AVI | D18: 17 | E18: 1 | G18: NOT DONE | I18: NOT DONE | K18: NOT DONE | M18: NOT DONE | O18: NOT DONE | Q18: NOT DONE | S18: NOT DONE | U18: NOT DONE | W18: NOT DONE | Y18: NOT DONE | AA18: NOT DONE | AB18: 45923 | AC18: DONE | AE18: NOT DONE | AG18: NOT DONE | AI18: NOT DONE | AK18: NOT DONE | AM18: NOT DONE | AO18: NOT DONE
A19: Q0576 | B19: Mohammed Fahim Mohammed Laffir | C19: CBF-AVI | D19: 17 | E19: 1 | G19: NOT DONE | I19: NOT DONE | K19: NOT DONE | M19: NOT DONE | O19: NOT DONE | Q19: NOT DONE | S19: NOT DONE | U19: NOT DONE | W19: NOT DONE | Y19: NOT DONE | AA19: NOT DONE | AB19: 45923 | AC19: DONE | AE19: NOT DONE | AG19: NOT DONE | AI19: NOT DONE | AK19: NOT DONE | AM19: NOT DONE | AO19: NOT DONE
A20: Q0610 | B20: Nelson Jr Ybut Sancho | C20: DFWH | D20: 0 | E20: 16 | F20: 45874 | G20: DONE | H20: 45874 | I20: DONE | J20: 45861 | K20: DONE | L20: 45873 | M20: DONE | N20: 45878 | O20: DONE | P20: 45875 | Q20: DONE | R20: 45861 | S20: DONE | T20: 45874 | U20: DONE | V20: 45873 | W20: DONE | X20: 45876 | Y20: DONE | Z20: 45861 | AA20: DONE | AB20: 46299 | AC20: DONE | AD20: 45873 | AE20: DONE | AF20: 45874 | AG20: DONE | AH20: 45876 | AI20: DONE | AJ20: 45875 | AK20: DONE | AL20: 45873 | AM20: DONE | AN20: 45876 | AO20: DONE
A21: Q0618 | B21: Joe Peter Angustia Pimentel | C21: DFWH | D21: 2 | E21: 14 | F21: 45960 | G21: DONE | H21: 45964 | I21: DONE | J21: 45956 | K21: DONE | L21: 45957 | M21: DONE | N21: 45964 | O21: DONE | P21: 45958 | Q21: DONE | R21: 45957 | S21: DONE | T21: 45957 | U21: DONE | V21: 45958 | W21: DONE | X21: 46300 | Y21: DONE | Z21: 46029 | AA21: DONE | AB21: 45995 | AC21: DONE | AD21: 46029 | AE21: DONE | AG21: NOT DONE | AH21: 45959 | AI21: DONE | AK21: NOT DONE | AL21: 45953 | AM21: DONE | AN21: 46028 | AO21: DONE
D22: 18 | E22: 0 | G22: NOT DONE | I22: NOT DONE | K22: NOT DONE | M22: NOT DONE | O22: NOT DONE | Q22: NOT DONE | S22: NOT DONE | U22: NOT DONE | W22: NOT DONE | Y22: NOT DONE | AA22: NOT DONE | AC22: NOT DONE | AE22: NOT DONE | AG22: NOT DONE | AI22: NOT DONE | AK22: NOT DONE | AM22: NOT DONE | AO22: NOT DONE
D23: 18 | E23: 0 | G23: NOT DONE | I23: NOT DONE | K23: NOT DONE | M23: NOT DONE | O23: NOT DONE | Q23: NOT DONE | S23: NOT DONE | U23: NOT DONE | W23: NOT DONE | Y23: NOT DONE | AA23: NOT DONE | AC23: NOT DONE | AE23: NOT DONE | AG23: NOT DONE | AI23: NOT DONE | AK23: NOT DONE | AM23: NOT DONE | AO23: NOT DONE
D24: 18 | E24: 0 | G24: NOT DONE | I24: NOT DONE | K24: NOT DONE | M24: NOT DONE | O24: NOT DONE | Q24: NOT DONE | S24: NOT DONE | U24: NOT DONE | W24: NOT DONE | Y24: NOT DONE | AA24: NOT DONE | AC24: NOT DONE | AE24: NOT DONE | AG24: NOT DONE | AI24: NOT DONE | AK24: NOT DONE | AM24: NOT DONE | AO24: NOT DONE
D25: 18 | E25: 0 | G25: NOT DONE | I25: NOT DONE | K25: NOT DONE | M25: NOT DONE | O25: NOT DONE | Q25: NOT DONE | S25: NOT DONE | U25: NOT DONE | W25: NOT DONE | Y25: NOT DONE | AA25: NOT DONE | AC25: NOT DONE | AE25: NOT DONE | AG25: NOT DONE | AI25: NOT DONE | AK25: NOT DONE | AM25: NOT DONE | AO25: NOT DONE

Sheet AMH Trainings
A1: Emp. No. | B1: Employee Name | C1: TEAM | D1: Count Of Trainings From June | E1: Count Of Trainings | F1: Date | G1: Safety Circuits and Controls | H1: Date | I1: Storage Retrieval Machine | J1: Date | K1: Flintec Weight Scale | L1: Date | M1: Chain and Roller conveyors | N1: Date | O1: Sorting Transfer Vehicle | P1: Date | Q1: AGC-MOS | R1: Date | S1: Logimat | T1: Date | U1: Warehouse Management(SOP) | V1: Date | W1: Bin Transport System | X1: Date | Y1: Electronic Hydraulic Press | Z1: Date | AA1: DEMAG JIB Crane Manual | AB1: Date | AC1: Foam Packing Machine
A2: Q0041 | B2: Destiny Emmanuel | C2: AMH | D2: 12 | E2: 0 | G2: NOT DONE | I2: NOT DONE | K2: NOT DONE | M2: NOT DONE | O2: NOT DONE | Q2: NOT DONE | S2: NOT DONE | U2: NOT DONE | W2: NOT DONE | Y2: NOT DONE | AA2: NOT DONE | AC2: NOT DONE
A3: Q0068 | B3: Ericson Murcillos Victorino | C3: AMH | D3: 12 | E3: 1 | G3: NOT DONE | I3: NOT DONE | K3: NOT DONE | L3: 45718 | M3: DONE | O3: NOT DONE | Q3: NOT DONE | S3: NOT DONE | U3: NOT DONE | W3: NOT DONE | Y3: NOT DONE | AA3: NOT DONE | AC3: NOT DONE
A4: Q0279 | B4: Manuel Jr. Esplago Feniza | C4: AMH | D4: 6 | E4: 9 | F4: 45834 | G4: DONE | H4: 46285 | I4: DONE | K4: NOT DONE | L4: 45622 | M4: DONE | N4: 45922 | O4: DONE | Q4: NOT DONE | R4: 45610 | S4: DONE | U4: NOT DONE | V4: 45680 | W4: DONE | X4: 45864 | Y4: DONE | Z4: 45922 | AA4: DONE | AB4: 45922 | AC4: DONE
A5: Q0282 | B5: Haren Del Campo | C5: AMH | D5: 6 | E5: 9 | F5: 45825 | G5: DONE | H5: 46285 | I5: DONE | K5: NOT DONE | L5: 45930 | M5: DONE | N5: 45774 | O5: DONE | Q5: NOT DONE | R5: 45610 | S5: DONE | U5: NOT DONE | V5: 45774 | W5: DONE | X5: 45913 | Y5: DONE | Z5: 45913 | AA5: DONE | AB5: 45913 | AC5: DONE
A6: Q0157 | B6: Edwin Balakid Tegli | C6: Resigned | D6: 10 | E6: 5 | F6: 45825 | G6: DONE | H6: 45565 | I6: DONE | K6: NOT DONE | L6: 45622 | M6: DONE | O6: NOT DONE | Q6: NOT DONE | R6: 45610 | S6: DONE | U6: NOT DONE | W6: NOT DONE | X6: 45859 | Y6: DONE | AA6: NOT DONE | AC6: NOT DONE
A7: Q0403 | B7: Marlon Rodel Fracisco Pimentel | C7: AMH | D7: 6 | E7: 9 | F7: 45832 | G7: DONE | H7: 46291 | I7: DONE | K7: NOT DONE | L7: 45635 | M7: DONE | N7: 45913 | O7: DONE | Q7: NOT DONE | R7: 45610 | S7: DONE | U7: NOT DONE | V7: 45809 | W7: DONE | X7: 45857 | Y7: DONE | Z7: 45913 | AA7: DONE | AB7: 45913 | AC7: DONE
A8: Q0446 | B8: Mario Dorado Hernandez | C8: CBF-AVI | D8: 14 | G8: NOT DONE | H8: 46306 | I8: DONE | K8: NOT DONE | L8: 46309 | M8: DONE | N8: 46306 | O8: DONE | R8: 46309 | S8: DONE
A9: Q0459 | B9: Jose Isagani Jr. Jamero Alaan | C9: AMH | D9: 6 | E9: 9 | F9: 45854 | G9: DONE | H9: 46275 | I9: DONE | K9: NOT DONE | L9: 46275 | M9: DONE | N9: 45669 | O9: DONE | Q9: NOT DONE | R9: 45610 | S9: DONE | U9: NOT DONE | V9: 45781 | W9: DONE | X9: 45857 | Y9: DONE | Z9: 45914 | AA9: DONE | AB9: 45914 | AC9: DONE
A10: Q0478 | B10: Paul Jeric Azul Falcatan | C10: AMH | D10: 5 | E10: 9 | F10: 45825 | G10: DONE | H10: 46275 | I10: DONE | K10: NOT DONE | L10: 46275 | M10: DONE | N10: 46217 | O10: DONE | Q10: NOT DONE | R10: 45610 | S10: DONE | U10: NOT DONE | V10: 45680 | W10: DONE | X10: 45859 | Y10: DONE | Z10: 45913 | AA10: DONE | AB10: 45913 | AC10: DONE
A11: Q0482 | B11: Jimmy Mallari Dela Cruz | C11: AMH | D11: 5 | E11: 9 | F11: 45834 | G11: DONE | H11: 46275 | I11: DONE | K11: NOT DONE | L11: 45916 | M11: DONE | N11: 45914 | O11: DONE | Q11: NOT DONE | R11: 45610 | S11: DONE | U11: NOT DONE | V11: 45784 | W11: DONE | X11: 45857 | Y11: DONE | Z11: 45914 | AA11: DONE | AB11: 45914 | AC11: DONE
A12: Q0492 | B12: Levitico Jose Caniedo | C12: AMH | D12: 12 | E12: 5 | F12: 45665 | G12: DONE | H12: 45565 | I12: DONE | K12: NOT DONE | L12: 45622 | M12: DONE | N12: 45669 | O12: DONE | Q12: NOT DONE | R12: 45610 | S12: DONE | U12: NOT DONE | W12: NOT DONE | Y12: NOT DONE | AA12: NOT DONE | AC12: NOT DONE
A13: Q0505 | B13: Edison Mendoza Rojas | C13: Resigned | D13: 7 | E13: 9 | F13: 45825 | G13: DONE | H13: 45787 | I13: DONE | K13: NOT DONE | L13: 45762 | M13: DONE | N13: 45827 | O13: DONE | Q13: NOT DONE | R13: 45788 | S13: DONE | V13: 45865 | W13: DONE | X13: 45839 | Y13: DONE | Z13: 45888 | AA13: DONE | AB13: 45888 | AC13: DONE
A14: Q0544 | B14: Jerico Tallorin Atienzo | C14: AMH | D14: 5 | E14: 9 | F14: 45834 | G14: DONE | H14: 46275 | I14: DONE | K14: NOT DONE | L14: 45916 | M14: DONE | N14: 45914 | O14: DONE | Q14: NOT DONE | R14: 45610 | S14: DONE | U14: NOT DONE | V14: 45680 | W14: DONE | X14: 45857 | Y14: DONE | Z14: 45914 | AA14: DONE | AB14: 45914 | AC14: DONE
A15: Q0548 | B15: Jayson Ruz Oligan | C15: AMH | D15: 7 | E15: 9 | F15: 45832 | G15: DONE | H15: 46285 | I15: DONE | K15: NOT DONE | L15: 45635 | M15: DONE | N15: 45775 | O15: DONE | Q15: NOT DONE | R15: 45610 | S15: DONE | U15: NOT DONE | V15: 45775 | W15: DONE | X15: 45857 | Y15: DONE | Z15: 45922 | AA15: DONE | AB15: 45922 | AC15: DONE
A16: Q0579 | B16: Pathmapriyan Muruguppilla | C16: AMH | D16: 8 | E16: 10 | F16: 45825 | G16: DONE | H16: 45599 | I16: DONE | K16: NOT DONE | L16: 45591 | M16: DONE | N16: 45774 | O16: DONE | P16: 45586 | Q16: DONE | R16: 45610 | S16: DONE | U16: NOT DONE | V16: 45774 | W16: DONE | X16: 45864 | Y16: DONE | Z16: 45913 | AA16: DONE | AB16: 45913 | AC16: DONE
A17: Q0583 | B17: Mabin Pauly | C17: AMH | D17: 12 | E17: 8 | F17: 45665 | G17: DONE | H17: 45551 | I17: DONE | K17: NOT DONE | L17: 45718 | M17: DONE | N17: 45669 | O17: DONE | P17: 45581 | Q17: DONE | R17: 45610 | S17: DONE | T17: 45581 | U17: DONE | V17: 45781 | W17: DONE | Y17: NOT DONE | AA17: NOT DONE | AC17: NOT DONE
A18: Q0585 | B18: Wai Hin Phyo | C18: AMH | D18: 6 | E18: 10 | F18: 45832 | G18: DONE | H18: 45718 | I18: DONE | K18: NOT DONE | L18: 45719 | M18: DONE | N18: 45930 | O18: DONE | P18: 45693 | Q18: DONE | R18: 45817 | S18: DONE | U18: NOT DONE | V18: 45830 | W18: DONE | X18: 45857 | Y18: DONE | Z18: 45875 | AA18: DONE | AB18: 45873 | AC18: DONE
A19: Q0596 | B19: Arvin Clyde D.Crisme | C19: AMH | D19: 7 | E19: 6 | F19: 45952 | G19: DONE | H19: 45981 | I19: DONE | L19: 45978 | M19: DONE | N19: 45980 | O19: DONE | Q19: NOT DONE | R19: 45981 | S19: DONE | U19: NOT DONE | V19: 45979 | W19: DONE | Y19: NOT DONE | AA19: NOT DONE | AC19: NOT DONE
